Workbook

Sheet START HERE
B2: SECURITY RISK QUANTIFICATION MODEL
B3: Navigation Guide — Start here. Follow the workflow left to right.
B6: 1 | C6: Assumptions · SET ONCE
C7: Configure your org's financial context — revenue, insurance coverage, risk appetite threshold, and severity-to-dollar mappings. Everything else derives from these inputs.
B11: 2 | C11: Issue Intake · WHEN NEW FINDINGS ARRIVE
C12: Paste raw findings from any scanner, audit, or pentest. Use the normalization guide to map to structured financial inputs. ALE, Residual ALE, and ROSI auto-calculate. Mark 'Yes' to transfer to Issue Register.
B16: 3 | C16: Issue Register · ONGOING — SOURCE OF TRUTH
C17: The master log of all issues. Each row is one issue with full financial context. Update Status (Open / In Remediation / Closed) and dates as issues progress. All other tabs pull from here.
B21: 4 | C21: Priority Ranking · WEEKLY — OPERATIONAL
C22: All open issues ranked by ROSI (financial return per remediation dollar). Shows Priority Tier, Days Open, and Recommended Action. Sprint Planning view surfaces your top 5 highest-return fixes.
B26: 5 | C26: Risk Domain Heat Map · MONTHLY — ANALYTICAL
C27: Domain-level ALE rollup and 5×5 likelihood/impact grid. Use to identify which security domains carry the most financial exposure and where to concentrate program investment.
B31: 6 | C31: Monthly Dashboard · MONTHLY — BOARD / EXEC
C32: Board and Risk Committee reporting view. Monthly pipeline table, KPI scorecard with RAG status, and pre-drafted narrative block. Portfolio ALE and ROSI KPIs update automatically.
B36: 7 | C36: ROSI & Prioritization · CALCULATION ENGINE
C37: Raw ROSI ranking data that feeds the Priority Ranking tab. Do not delete. Refer to Priority Ranking for the full prioritization view.
B41: Workflow: Assumptions → Issue Intake → Issue Register → Priority Ranking → Heat Map → Monthly Dashboard

Sheet Issue Intake
A1: SECURITY ISSUE INTAKE — RAW FINDING NORMALIZER
A2: Paste raw findings from any scanner, audit, or manual review. Map each to structured financial inputs. Blue cells = your inputs. Black cells = auto-calculated. Use Issue ID to link to Issue Register.
A4: A. NORMALIZATION REFERENCE — Mapping Raw Finding Language to Structured Inputs
A5: Raw Finding Type | C5: Example Language | E5: Risk Domain | G5: Suggested Severity | I5: Typical Threat Frequency (annual) | K5: Typical Vulnerability Prob. | M5: Calibration Note
A6: Vulnerability Scanner (Nessus/Qualys/Tenable) | C6: Critical: Remote code execution CVE-2024-XXXXX on internet-facing host | E6: Infrastructure | G6: Critical | I6: 0.7 – 0.9 (internet-facing) | K6: 0.8 – 0.95 | M6: Use CVSS exploitability score as proxy for Vuln Prob. EPSS score if available.
A7: Cloud Posture (CSPM / Security Hub) | C7: S3 bucket with public access enabled, contains PII | E7: Data Protection | G7: High | I7: 0.5 – 0.7 (opportunistic scan) | K7: 0.6 – 0.8 | M7: Frequency = likelihood of opportunistic attacker finding misconfiguration. Loss magnitude = data classification × records exposed.
A8: Identity Audit (IAM / AD Review) | C8: Privileged accounts without MFA — 47 accounts | E8: Identity & Access | G8: High | I8: 0.6 – 0.8 (credential attacks) | K8: 0.7 – 0.85 | M8: Scale ALE by account count × avg privilege level. Admin accounts 3–5× standard user ALE.
A9: Penetration Test (Manual) | C9: SQL injection in authenticated customer portal — High severity | E9: Application | G9: Critical | I9: 0.3 – 0.6 (targeted attack) | K9: 0.7 – 0.9 | M9: Pentest findings = confirmed vulnerability. Set Vuln Prob at high end. Loss magnitude includes breach notification, regulatory fines.
A10: Compliance / Audit (SOC 2 / ISO gap) | C10: No formal vendor risk assessment process — control gap | E10: Third-Party Risk | G10: Medium | I10: 0.2 – 0.4 (indirect via vendor) | K10: 0.4 – 0.6 | M10: Compliance gaps = process risk, not technical exploit. Use conservative frequency. Loss = regulatory exposure + audit finding cost.
A11: SIEM / Detection (Alert / Anomaly) | C11: 30 endpoints not sending logs to SIEM — detection blind spot | E11: Detection & Response | G11: Medium–High | I11: 0.3 – 0.5 (incident going undetected) | K11: 0.5 – 0.7 | M11: Model as: detection failure increases dwell time, which increases loss magnitude. Add dwell-time multiplier to base financial impact.
A12: Patch Management (Patch Gap) | C12: Windows Server — critical patch 45 days overdue (CVE-2024-38124) | E12: Infrastructure | G12: Critical | I12: 0.6 – 0.85 (known exploit in wild) | K12: 0.85 – 0.95 | M12: Check CISA KEV list for active exploitation. If on KEV, set frequency at 0.85+. Days-exposed increases Vuln Prob over time.
A14: B. ISSUE INTAKE FORM — Enter Raw Findings Below (one row per issue)
A15: Issue ID (auto or manual) | B15: Raw Finding Text (paste as-is from scanner/audit) | C15: Source Tool / Scanner | D15: Date Found | E15: Proposed Risk Domain | F15: Proposed Severity (C/H/M/L) | G15: Asset Value at Risk ($) | H15: Threat Freq. (annual, 0–1) | I15: Vulnerability Prob. (0–1) | J15: Existing Control Factor (0=none, 1=full) | K15: Est. Remediation Cost ($) | L15: ALE ($) [auto] | M15: Residual ALE ($) [auto] | N15: ROSI [auto] | O15: Priority Score [auto] | P15: Transfer to Issue Register?
A16: =IF(B16<>"","NEW-"&TEXT(1,"000"),"") | L16: =IF(G16="","",G16*H16*I16*(1-J16)) | M16: =IF(L16="","",L16*(J16)) | N16: =IF(K16="","",IF(K16=0,"N/A",(L16-M16-K16)/K16)) | O16: =IF(L16="","",L16/MAX(K16,1))
A17: =IF(B17<>"","NEW-"&TEXT(2,"000"),"") | L17: =IF(G17="","",G17*H17*I17*(1-J17)) | M17: =IF(L17="","",L17*(J17)) | N17: =IF(K17="","",IF(K17=0,"N/A",(L17-M17-K17)/K17)) | O17: =IF(L17="","",L17/MAX(K17,1))
A18: =IF(B18<>"","NEW-"&TEXT(3,"000"),"") | L18: =IF(G18="","",G18*H18*I18*(1-J18)) | M18: =IF(L18="","",L18*(J18)) | N18: =IF(K18="","",IF(K18=0,"N/A",(L18-M18-K18)/K18)) | O18: =IF(L18="","",L18/MAX(K18,1))
A19: =IF(B19<>"","NEW-"&TEXT(4,"000"),"") | L19: =IF(G19="","",G19*H19*I19*(1-J19)) | M19: =IF(L19="","",L19*(J19)) | N19: =IF(K19="","",IF(K19=0,"N/A",(L19-M19-K19)/K19)) | O19: =IF(L19="","",L19/MAX(K19,1))
A20: =IF(B20<>"","NEW-"&TEXT(5,"000"),"") | L20: =IF(G20="","",G20*H20*I20*(1-J20)) | M20: =IF(L20="","",L20*(J20)) | N20: =IF(K20="","",IF(K20=0,"N/A",(L20-M20-K20)/K20)) | O20: =IF(L20="","",L20/MAX(K20,1))
A21: =IF(B21<>"","NEW-"&TEXT(6,"000"),"") | L21: =IF(G21="","",G21*H21*I21*(1-J21)) | M21: =IF(L21="","",L21*(J21)) | N21: =IF(K21="","",IF(K21=0,"N/A",(L21-M21-K21)/K21)) | O21: =IF(L21="","",L21/MAX(K21,1))
A22: =IF(B22<>"","NEW-"&TEXT(7,"000"),"") | L22: =IF(G22="","",G22*H22*I22*(1-J22)) | M22: =IF(L22="","",L22*(J22)) | N22: =IF(K22="","",IF(K22=0,"N/A",(L22-M22-K22)/K22)) | O22: =IF(L22="","",L22/MAX(K22,1))
A23: =IF(B23<>"","NEW-"&TEXT(8,"000"),"") | L23: =IF(G23="","",G23*H23*I23*(1-J23)) | M23: =IF(L23="","",L23*(J23)) | N23: =IF(K23="","",IF(K23=0,"N/A",(L23-M23-K23)/K23)) | O23: =IF(L23="","",L23/MAX(K23,1))
A24: =IF(B24<>"","NEW-"&TEXT(9,"000"),"") | L24: =IF(G24="","",G24*H24*I24*(1-J24)) | M24: =IF(L24="","",L24*(J24)) | N24: =IF(K24="","",IF(K24=0,"N/A",(L24-M24-K24)/K24)) | O24: =IF(L24="","",L24/MAX(K24,1))
A25: =IF(B25<>"","NEW-"&TEXT(10,"000"),"") | L25: =IF(G25="","",G25*H25*I25*(1-J25)) | M25: =IF(L25="","",L25*(J25)) | N25: =IF(K25="","",IF(K25=0,"N/A",(L25-M25-K25)/K25)) | O25: =IF(L25="","",L25/MAX(K25,1))
A26: =IF(B26<>"","NEW-"&TEXT(11,"000"),"") | L26: =IF(G26="","",G26*H26*I26*(1-J26)) | M26: =IF(L26="","",L26*(J26)) | N26: =IF(K26="","",IF(K26=0,"N/A",(L26-M26-K26)/K26)) | O26: =IF(L26="","",L26/MAX(K26,1))
A27: =IF(B27<>"","NEW-"&TEXT(12,"000"),"") | L27: =IF(G27="","",G27*H27*I27*(1-J27)) | M27: =IF(L27="","",L27*(J27)) | N27: =IF(K27="","",IF(K27=0,"N/A",(L27-M27-K27)/K27)) | O27: =IF(L27="","",L27/MAX(K27,1))
A28: =IF(B28<>"","NEW-"&TEXT(13,"000"),"") | L28: =IF(G28="","",G28*H28*I28*(1-J28)) | M28: =IF(L28="","",L28*(J28)) | N28: =IF(K28="","",IF(K28=0,"N/A",(L28-M28-K28)/K28)) | O28: =IF(L28="","",L28/MAX(K28,1))
A29: =IF(B29<>"","NEW-"&TEXT(14,"000"),"") | L29: =IF(G29="","",G29*H29*I29*(1-J29)) | M29: =IF(L29="","",L29*(J29)) | N29: =IF(K29="","",IF(K29=0,"N/A",(L29-M29-K29)/K29)) | O29: =IF(L29="","",L29/MAX(K29,1))
A30: =IF(B30<>"","NEW-"&TEXT(15,"000"),"") | L30: =IF(G30="","",G30*H30*I30*(1-J30)) | M30: =IF(L30="","",L30*(J30)) | N30: =IF(K30="","",IF(K30=0,"N/A",(L30-M30-K30)/K30)) | O30: =IF(L30="","",L30/MAX(K30,1))
A31: =IF(B31<>"","NEW-"&TEXT(16,"000"),"") | L31: =IF(G31="","",G31*H31*I31*(1-J31)) | M31: =IF(L31="","",L31*(J31)) | N31: =IF(K31="","",IF(K31=0,"N/A",(L31-M31-K31)/K31)) | O31: =IF(L31="","",L31/MAX(K31,1))
A32: =IF(B32<>"","NEW-"&TEXT(17,"000"),"") | L32: =IF(G32="","",G32*H32*I32*(1-J32)) | M32: =IF(L32="","",L32*(J32)) | N32: =IF(K32="","",IF(K32=0,"N/A",(L32-M32-K32)/K32)) | O32: =IF(L32="","",L32/MAX(K32,1))
A33: =IF(B33<>"","NEW-"&TEXT(18,"000"),"") | L33: =IF(G33="","",G33*H33*I33*(1-J33)) | M33: =IF(L33="","",L33*(J33)) | N33: =IF(K33="","",IF(K33=0,"N/A",(L33-M33-K33)/K33)) | O33: =IF(L33="","",L33/MAX(K33,1))
A34: =IF(B34<>"","NEW-"&TEXT(19,"000"),"") | L34: =IF(G34="","",G34*H34*I34*(1-J34)) | M34: =IF(L34="","",L34*(J34)) | N34: =IF(K34="","",IF(K34=0,"N/A",(L34-M34-K34)/K34)) | O34: =IF(L34="","",L34/MAX(K34,1))
A35: =IF(B35<>"","NEW-"&TEXT(20,"000"),"") | L35: =IF(G35="","",G35*H35*I35*(1-J35)) | M35: =IF(L35="","",L35*(J35)) | N35: =IF(K35="","",IF(K35=0,"N/A",(L35-M35-K35)/K35)) | O35: =IF(L35="","",L35/MAX(K35,1))
A36: TOTALS | L36: =SUM(L16:L35) -> 0 | M36: =SUM(M16:M35) -> 0 | O36: =SUM(O16:O35) -> 0
A38: C. CALIBRATION TIPS — How to Set Threat Frequency and Vulnerability Probability from Real Data
A39: Threat Frequency | D39: SIEM data: count credential-based alert events over 90 days → annualize. Verizon DBIR: industry-specific breach frequency rates. CISA KEV: if CVE is on KEV list, set frequency ≥ 0.7.
A40: Vulnerability Probability | D40: CVSS exploitability sub-score ÷ 10 as starting point. EPSS score (empirical probability of exploitation within 30 days) × 12 for annual. Pentest finding = confirmed → set 0.8+. Scanner finding = potential → set 0.4–0.6.
A41: Asset Value at Risk | D41: Revenue at risk per system: Annual Revenue ÷ 8,760 hrs × Max Downtime hrs. Data breach cost: records × avg cost per record ($150–$250 per Ponemon). Regulatory fine exposure: GDPR up to 4% global revenue; HIPAA up to $1.9M per violation category.
A42: Control Effectiveness Factor | D42: 0.0 = No controls in place (full ALE). 0.25 = Strong compensating controls (residual 25% of raw ALE). 0.5 = Partial controls. 0.75 = Minimal controls. Source: NIST SP 800-53 control effectiveness ratings; CIS Control implementation groups.

Sheet Issue Register
A1: SECURITY ISSUE REGISTER — RISK QUANTIFICATION
A2: Source of truth for all security issues. Each row is one issue. Blue = input. Black = calculated. Update status/dates as issues progress.
A3: Issue ID | B3: Issue Description | C3: Source / Scanner | D3: Date Ingested | E3: Target Remediation Date | F3: Date Closed | G3: Status | H3: Risk Domain | I3: Raw Severity (C/H/M/L) | J3: Numeric Severity Score | K3: Likelihood Score | L3: Control Effective. Factor | M3: Risk Score (Calculated) | N3: Residual Risk Score | O3: Base Financial Impact ($) | P3: Probability of Exploit | Q3: ALE ($) (Annual) | R3: Remediation Cost ($) | S3: ROSI
A4: SEC-001 | B4: Unpatched critical RCE in internet-facing web app | C4: Tenable / Nessus | D4: 2024-10-03 | E4: 2024-10-17 | G4: Open | H4: Infrastructure | I4: Critical | J4: 10 | K4: 0.9 | L4: 0.85 | M4: =J4*K4*L4 -> 7.65 | N4: =M4*(1-(L4*0.3)) -> 5.69925 | O4: 250000 | P4: 0.9 | Q4: =O4*P4 -> 225000 | R4: 25000 | S4: =IF(R4>0,(Q4-R4)/R4,"N/A") -> 8
A5: SEC-002 | B5: Default credentials on network device (firewall) | C5: Manual Pentest | D5: 2024-10-05 | E5: 2024-10-12 | F5: 2024-10-15 | G5: Closed | H5: Network | I5: Critical | J5: 10 | K5: 0.9 | L5: 0.9 | M5: =J5*K5*L5 -> 8.1 | N5: =M5*(1-(L5*0.3)) -> 5.913 | O5: 250000 | P5: 0.9 | Q5: =O5*P5 -> 225000 | R5: 30000 | S5: =IF(R5>0,(Q5-R5)/R5,"N/A") -> 6.5
A6: SEC-003 | B6: Sensitive PII stored unencrypted in S3 bucket | C6: Cloud Security Posture | D6: 2024-10-08 | E6: 2024-10-31 | G6: Open | H6: Data Protection | I6: High | J6: 7 | K6: 0.65 | L6: 0.7 | M6: =J6*K6*L6 -> 3.185 | N6: =M6*(1-(L6*0.3)) -> 2.51615 | O6: 1500000 | P6: 0.65 | Q6: =O6*P6 -> 975000 | R6: 45000 | S6: =IF(R6>0,(Q6-R6)/R6,"N/A") -> 20.666667
A7: SEC-004 | B7: MFA not enforced for privileged admin accounts | C7: Identity Audit | D7: 2024-10-10 | E7: 2024-10-24 | F7: 2024-10-28 | G7: Closed | H7: Identity & Access | I7: High | J7: 7 | K7: 0.65 | L7: 0.75 | M7: =J7*K7*L7 -> 3.4125 | N7: =M7*(1-(L7*0.3)) -> 2.6446875 | O7: 1500000 | P7: 0.65 | Q7: =O7*P7 -> 975000 | R7: 18000 | S7: =IF(R7>0,(Q7-R7)/R7,"N/A") -> 53.166667
A8: SEC-005 | B8: Outdated TLS 1.0 on internal API gateway | C8: Qualys | D8: 2024-10-12 | E8: 2024-11-15 | G8: Open | H8: Network | I8: High | J8: 7 | K8: 0.65 | L8: 0.6 | M8: =J8*K8*L8 -> 2.73 | N8: =M8*(1-(L8*0.3)) -> 2.2386 | O8: 1500000 | P8: 0.65 | Q8: =O8*P8 -> 975000 | R8: 22000 | S8: =IF(R8>0,(Q8-R8)/R8,"N/A") -> 43.318182
A9: SEC-006 | B9: SQL injection vulnerability in customer portal | C9: DAST / Burp | D9: 2024-10-15 | E9: 2024-10-29 | G9: In Remediation | H9: Application | I9: Critical | J9: 10 | K9: 0.9 | L9: 0.8 | M9: =J9*K9*L9 -> 7.2 | N9: =M9*(1-(L9*0.3)) -> 5.472 | O9: 5000000 | P9: 0.9 | Q9: =O9*P9 -> 4500000 | R9: 65000 | S9: =IF(R9>0,(Q9-R9)/R9,"N/A") -> 68.230769
A10: SEC-007 | B10: Missing security headers on marketing website | C10: Web Scan | D10: 2024-10-18 | E10: 2024-11-30 | G10: Open | H10: Application | I10: Low | J10: 2 | K10: 0.1 | L10: 0.3 | M10: =J10*K10*L10 -> 0.06 | N10: =M10*(1-(L10*0.3)) -> 0.0546 | O10: 75000 | P10: 0.1 | Q10: =O10*P10 -> 7500 | R10: 5000 | S10: =IF(R10>0,(Q10-R10)/R10,"N/A") -> 0.5
A11: SEC-008 | B11: Endpoint without EDR agent (30 devices) | C11: SIEM / Asset Inv. | D11: 2024-10-20 | E11: 2024-11-08 | G11: Open | H11: Endpoint | I11: Medium | J11: 4 | K11: 0.35 | L11: 0.55 | M11: =J11*K11*L11 -> 0.77 | N11: =M11*(1-(L11*0.3)) -> 0.64295 | O11: 350000 | P11: 0.35 | Q11: =O11*P11 -> 122500 | R11: 35000 | S11: =IF(R11>0,(Q11-R11)/R11,"N/A") -> 2.5
A12: SEC-009 | B12: Stale privileged accounts (90+ days inactive) | C12: AD Audit | D12: 2024-10-22 | E12: 2024-11-01 | F12: 2024-11-05 | G12: Closed | H12: Identity & Access | I12: Medium | J12: 4 | K12: 0.35 | L12: 0.65 | M12: =J12*K12*L12 -> 0.91 | N12: =M12*(1-(L12*0.3)) -> 0.73255 | O12: 350000 | P12: 0.35 | Q12: =O12*P12 -> 122500 | R12: 8000 | S12: =IF(R12>0,(Q12-R12)/R12,"N/A") -> 14.3125
A13: SEC-010 | B13: Insecure direct object reference in HR app | C13: Code Review | D13: 2024-10-25 | E13: 2024-11-20 | G13: Open | H13: Application | I13: High | J13: 7 | K13: 0.65 | L13: 0.7 | M13: =J13*K13*L13 -> 3.185 | N13: =M13*(1-(L13*0.3)) -> 2.51615 | O13: 1500000 | P13: 0.65 | Q13: =O13*P13 -> 975000 | R13: 28000 | S13: =IF(R13>0,(Q13-R13)/R13,"N/A") -> 33.821429
A14: SEC-011 | B14: Log ingestion gaps — 3 critical systems not in SIEM | C14: SIEM Review | D14: 2024-11-01 | E14: 2024-11-22 | G14: In Remediation | H14: Detection & Response | I14: 7 | J14: 7 | K14: 0.65 | L14: 0.5 | M14: =J14*K14*L14 -> 2.275 | N14: =M14*(1-(L14*0.3)) -> 1.93375 | O14: 1500000 | P14: 0.65 | Q14: =O14*P14 -> 975000 | R14: 42000 | S14: =IF(R14>0,(Q14-R14)/R14,"N/A") -> 22.214286
A15: SEC-012 | B15: Third-party vendor with excessive data access | C15: Vendor Assessment | D15: 2024-11-04 | E15: 2024-11-30 | G15: Open | H15: Third-Party Risk | I15: High | J15: 7 | K15: 0.65 | L15: 0.6 | M15: =J15*K15*L15 -> 2.73 | N15: =M15*(1-(L15*0.3)) -> 2.2386 | O15: 1500000 | P15: 0.65 | Q15: =O15*P15 -> 975000 | R15: 15000 | S15: =IF(R15>0,(Q15-R15)/R15,"N/A") -> 64
A16: SEC-013 | B16: Missing patch — Windows Server 2019 (CVE-2024-38124) | C16: Patch Mgmt | D16: 2024-11-06 | E16: 2024-11-13 | F16: 2024-11-12 | G16: Closed | H16: Infrastructure | I16: Critical | J16: 10 | K16: 0.9 | L16: 0.9 | M16: =J16*K16*L16 -> 8.1 | N16: =M16*(1-(L16*0.3)) -> 5.913 | O16: 5000000 | P16: 0.9 | Q16: =O16*P16 -> 4500000 | R16: 12000 | S16: =IF(R16>0,(Q16-R16)/R16,"N/A") -> 374
A17: SEC-014 | B17: DLP not configured for outbound email | C17: DLP Policy Review | D17: 2024-11-08 | E17: 2024-12-15 | G17: Open | H17: Data Protection | I17: Medium | J17: 4 | K17: 0.35 | L17: 0.45 | M17: =J17*K17*L17 -> 0.63 | N17: =M17*(1-(L17*0.3)) -> 0.54495 | O17: 350000 | P17: 0.35 | Q17: =O17*P17 -> 122500 | R17: 55000 | S17: =IF(R17>0,(Q17-R17)/R17,"N/A") -> 1.2272727
A18: SEC-015 | B18: Container images with known HIGH CVEs in prod | C18: Container Scan | D18: 2024-11-10 | E18: 2024-11-24 | G18: Open | H18: Infrastructure | I18: High | J18: 7 | K18: 0.65 | L18: 0.65 | M18: =J18*K18*L18 -> 2.9575 | N18: =M18*(1-(L18*0.3)) -> 2.3807875 | O18: 1500000 | P18: 0.65 | Q18: =O18*P18 -> 975000 | R18: 32000 | S18: =IF(R18>0,(Q18-R18)/R18,"N/A") -> 29.46875
A19: TOTALS / PORTFOLIO SUMMARY | J19: =AVERAGE(J4:J18) -> 6.8666667 | K19: =AVERAGE(K4:K18) -> 0.62 | L19: =AVERAGE(L4:L18) -> 0.66 | M19: =AVERAGE(M4:M18) -> 3.593 | N19: =AVERAGE(N4:N18) -> 2.762735 | O19: =SUM(O4:O18) -> 22125000 | P19: =AVERAGE(P4:P18) -> 0.62 | Q19: =SUM(Q4:Q18) -> 16650000 | R19: =SUM(R4:R18) -> 437000

Sheet Priority Ranking
A1: SECURITY ISSUE PRIORITIZATION ENGINE — RANKED BY FINANCIAL IMPACT PER REMEDIATION DOLLAR
A2: All open issues from the Issue Register, ranked by ROSI descending. Highest-return remediations at the top. Color bands show priority tier. Use this view to build your remediation sprint plan.
A4: A. PORTFOLIO SUMMARY — Current Open Issues
A5: Total Open Issues | C5: Total Portfolio ALE ($) | E5: Total Remediation Budget Needed ($) | G5: Avg ROSI (open issues) | I5: Issues Above Risk Appetite | K5: Est. ALE Reduction if Top 5 Fixed
A6: =COUNTIF('Issue Register'!G:G,"Open")+COUNTIF('Issue Register'!G:G,"In Remediation") -> 11 | C6: =SUMIF('Issue Register'!G:G,"Open",'Issue Register'!Q:Q)+SUMIF('Issue Register'!G:G,"In Remediation",'Issue Register'!Q:Q) -> 10827500 | E6: =SUMIF('Issue Register'!G:G,"Open",'Issue Register'!R:R)+SUMIF('Issue Register'!G:G,"In Remediation",'Issue Register'!R:R) -> 369000 | G6: =IFERROR(AVERAGEIF('Issue Register'!G:G,"Open",'Issue Register'!S:S),0) -> 22.611367 | I6: =COUNTIFS('Issue Register'!G:G,"Open",'Issue Register'!Q:Q,">"&Assumptions!B11) -> 0 | K6: =SUMPRODUCT(LARGE(IF('Issue Register'!G:G="Open",'Issue Register'!Q:Q,0),{1,2,3,4,5}))*0.8 -> 3900000
A8: B. PRIORITY TIER LEGEND
A9: Tier | C9: Color Code | E9: ROSI / ALE Threshold | G9: Recommended Action
A10: TIER 1 — IMMEDIATE | C10: ● | E10: ROSI > 20x OR ALE > $2M | G10: Fix within 7 days. No budget conversation needed.
A11: TIER 2 — HIGH PRIORITY | C11: ● | E11: ROSI 10x–20x OR ALE $500K–$2M | G11: Fix within 30 days. Include in next sprint.
A12: TIER 3 — STANDARD | C12: ● | E12: ROSI 3x–10x OR ALE $100K–$500K | G12: Fix within 90 days. Schedule in roadmap.
A13: TIER 4 — MONITOR | C13: ● | E13: ROSI 1x–3x OR ALE < $100K | G13: Fix when capacity allows. Consider risk acceptance.
A14: TIER 5 — DEPRIORITIZE | C14: ● | E14: ROSI < 1x | G14: Cost exceeds benefit. Formally accept or transfer risk.
A16: C. RANKED REMEDIATION BACKLOG — All Open Issues Sorted by Financial Priority
A17: Priority Rank | B17: Issue ID | C17: Description | D17: Risk Domain | E17: Severity | F17: Status | G17: ALE ($) | H17: Remediation Cost ($) | I17: Risk Reduction % | J17: Financial Benefit ($) | K17: ROSI | L17: Priority Tier | M17: Days Open | N17: Recommended Action
A18: =IF('ROSI & Prioritization'!B5<>"",1,"") | B18: =IF('ROSI & Prioritization'!A5<>"",'ROSI & Prioritization'!A5,"") -> REMEDIATION PRIORITIZATION — RANKED BY FINANCIAL RISK REDUCTION | C18: =IF('ROSI & Prioritization'!B5<>"",'ROSI & Prioritization'!B5,"") | D18: =IF(B18<>"",IFERROR(VLOOKUP(B18,'Issue Register'!A:H,8,0),""),"") | E18: =IF('ROSI & Prioritization'!C5<>"",'ROSI & Prioritization'!C5,"") | F18: =IF(B18<>"",IFERROR(VLOOKUP(B18,'Issue Register'!A:G,7,0),""),"") | G18: =IF('ROSI & Prioritization'!D5<>"",'ROSI & Prioritization'!D5,"") | H18: =IF('ROSI & Prioritization'!E5<>"",'ROSI & Prioritization'!E5,"") | I18: =IF('ROSI & Prioritization'!F5<>"",'ROSI & Prioritization'!F5,"") | J18: =IF('ROSI & Prioritization'!G5<>"",'ROSI & Prioritization'!G5,"") | K18: =IF('ROSI & Prioritization'!H5<>"",'ROSI & Prioritization'!H5,"") | L18: =IF(K18="","",IF(K18>20,"TIER 1 — IMMEDIATE",IF(K18>=10,"TIER 2 — HIGH PRIORITY",IF(K18>=3,"TIER 3 — STANDARD",IF(K18>=1,"TIER 4 — MONITOR","TIER 5 — DEPRIORITIZE"))))) | M18: =IF(B18<>"",IFERROR(TODAY()-VLOOKUP(B18,'Issue Register'!A:D,4,0),""),"") | N18: =IF(K18="","",IF(K18>20,"Immediate — no budget gate",IF(K18>=10,"Fix within 30 days",IF(K18>=3,"Schedule in 90-day roadmap",IF(K18>=1,"Accept or transfer risk","Formally accept — deprioritize")))))
A19: =IF('ROSI & Prioritization'!B6<>"",2,"") -> 2 | B19: =IF('ROSI & Prioritization'!A6<>"",'ROSI & Prioritization'!A6,"") -> Issue ID | C19: =IF('ROSI & Prioritization'!B6<>"",'ROSI & Prioritization'!B6,"") -> Description | D19: =IF(B19<>"",IFERROR(VLOOKUP(B19,'Issue Register'!A:H,8,0),""),"") -> Risk Domain | E19: =IF('ROSI & Prioritization'!C6<>"",'ROSI & Prioritization'!C6,"") -> Severity | F19: =IF(B19<>"",IFERROR(VLOOKUP(B19,'Issue Register'!A:G,7,0),""),"") -> Status | G19: =IF('ROSI & Prioritization'!D6<>"",'ROSI & Prioritization'!D6,"") -> ALE ($) | H19: =IF('ROSI & Prioritization'!E6<>"",'ROSI & Prioritization'!E6,"") -> Remediation Cost ($) | I19: =IF('ROSI & Prioritization'!F6<>"",'ROSI & Prioritization'!F6,"") -> Risk Reduction Expected | J19: =IF('ROSI & Prioritization'!G6<>"",'ROSI & Prioritization'!G6,"") -> Financial Benefit ($) | K19: =IF('ROSI & Prioritization'!H6<>"",'ROSI & Prioritization'!H6,"") -> ROSI | L19: =IF(K19="","",IF(K19>20,"TIER 1 — IMMEDIATE",IF(K19>=10,"TIER 2 — HIGH PRIORITY",IF(K19>=3,"TIER 3 — STANDARD",IF(K19>=1,"TIER 4 — MONITOR","TIER 5 — DEPRIORITIZE"))))) -> TIER 1 — IMMEDIATE | M19: =IF(B19<>"",IFERROR(TODAY()-VLOOKUP(B19,'Issue Register'!A:D,4,0),""),"") | N19: =IF(K19="","",IF(K19>20,"Immediate — no budget gate",IF(K19>=10,"Fix within 30 days",IF(K19>=3,"Schedule in 90-day roadmap",IF(K19>=1,"Accept or transfer risk","Formally accept — deprioritize"))))) -> Immediate — no budget gate
A20: =IF('ROSI & Prioritization'!B7<>"",3,"") -> 3 | B20: =IF('ROSI & Prioritization'!A7<>"",'ROSI & Prioritization'!A7,"") -> SEC-001 | C20: =IF('ROSI & Prioritization'!B7<>"",'ROSI & Prioritization'!B7,"") -> Unpatched RCE - Web App | D20: =IF(B20<>"",IFERROR(VLOOKUP(B20,'Issue Register'!A:H,8,0),""),"") -> Infrastructure | E20: =IF('ROSI & Prioritization'!C7<>"",'ROSI & Prioritization'!C7,"") -> Critical | F20: =IF(B20<>"",IFERROR(VLOOKUP(B20,'Issue Register'!A:G,7,0),""),"") -> Open | G20: =IF('ROSI & Prioritization'!D7<>"",'ROSI & Prioritization'!D7,"") -> 4500000 | H20: =IF('ROSI & Prioritization'!E7<>"",'ROSI & Prioritization'!E7,"") -> 25000 | I20: =IF('ROSI & Prioritization'!F7<>"",'ROSI & Prioritization'!F7,"") -> 0.9 | J20: =IF('ROSI & Prioritization'!G7<>"",'ROSI & Prioritization'!G7,"") -> 4050000 | K20: =IF('ROSI & Prioritization'!H7<>"",'ROSI & Prioritization'!H7,"") -> 161 | L20: =IF(K20="","",IF(K20>20,"TIER 1 — IMMEDIATE",IF(K20>=10,"TIER 2 — HIGH PRIORITY",IF(K20>=3,"TIER 3 — STANDARD",IF(K20>=1,"TIER 4 — MONITOR","TIER 5 — DEPRIORITIZE"))))) -> TIER 1 — IMMEDIATE | M20: =IF(B20<>"",IFERROR(TODAY()-VLOOKUP(B20,'Issue Register'!A:D,4,0),""),"") -> 597 | N20: =IF(K20="","",IF(K20>20,"Immediate — no budget gate",IF(K20>=10,"Fix within 30 days",IF(K20>=3,"Schedule in 90-day roadmap",IF(K20>=1,"Accept or transfer risk","Formally accept — deprioritize"))))) -> Immediate — no budget gate
A21: =IF('ROSI & Prioritization'!B8<>"",4,"") -> 4 | B21: =IF('ROSI & Prioritization'!A8<>"",'ROSI & Prioritization'!A8,"") -> SEC-006 | C21: =IF('ROSI & Prioritization'!B8<>"",'ROSI & Prioritization'!B8,"") -> SQL Injection - Customer Portal | D21: =IF(B21<>"",IFERROR(VLOOKUP(B21,'Issue Register'!A:H,8,0),""),"") -> Application | E21: =IF('ROSI & Prioritization'!C8<>"",'ROSI & Prioritization'!C8,"") -> Critical | F21: =IF(B21<>"",IFERROR(VLOOKUP(B21,'Issue Register'!A:G,7,0),""),"") -> In Remediation | G21: =IF('ROSI & Prioritization'!D8<>"",'ROSI & Prioritization'!D8,"") -> 4500000 | H21: =IF('ROSI & Prioritization'!E8<>"",'ROSI & Prioritization'!E8,"") -> 65000 | I21: =IF('ROSI & Prioritization'!F8<>"",'ROSI & Prioritization'!F8,"") -> 0.85 | J21: =IF('ROSI & Prioritization'!G8<>"",'ROSI & Prioritization'!G8,"") -> 3825000 | K21: =IF('ROSI & Prioritization'!H8<>"",'ROSI & Prioritization'!H8,"") -> 57.846154 | L21: =IF(K21="","",IF(K21>20,"TIER 1 — IMMEDIATE",IF(K21>=10,"TIER 2 — HIGH PRIORITY",IF(K21>=3,"TIER 3 — STANDARD",IF(K21>=1,"TIER 4 — MONITOR","TIER 5 — DEPRIORITIZE"))))) -> TIER 1 — IMMEDIATE | M21: =IF(B21<>"",IFERROR(TODAY()-VLOOKUP(B21,'Issue Register'!A:D,4,0),""),"") -> 585 | N21: =IF(K21="","",IF(K21>20,"Immediate — no budget gate",IF(K21>=10,"Fix within 30 days",IF(K21>=3,"Schedule in 90-day roadmap",IF(K21>=1,"Accept or transfer risk","Formally accept — deprioritize"))))) -> Immediate — no budget gate
A22: =IF('ROSI & Prioritization'!B9<>"",5,"") -> 5 | B22: =IF('ROSI & Prioritization'!A9<>"",'ROSI & Prioritization'!A9,"") -> SEC-012 | C22: =IF('ROSI & Prioritization'!B9<>"",'ROSI & Prioritization'!B9,"") -> Vendor Excessive Data Access | D22: =IF(B22<>"",IFERROR(VLOOKUP(B22,'Issue Register'!A:H,8,0),""),"") -> Third-Party Risk | E22: =IF('ROSI & Prioritization'!C9<>"",'ROSI & Prioritization'!C9,"") -> High | F22: =IF(B22<>"",IFERROR(VLOOKUP(B22,'Issue Register'!A:G,7,0),""),"") -> Open | G22: =IF('ROSI & Prioritization'!D9<>"",'ROSI & Prioritization'!D9,"") -> 975000 | H22: =IF('ROSI & Prioritization'!E9<>"",'ROSI & Prioritization'!E9,"") -> 15000 | I22: =IF('ROSI & Prioritization'!F9<>"",'ROSI & Prioritization'!F9,"") -> 0.6 | J22: =IF('ROSI & Prioritization'!G9<>"",'ROSI & Prioritization'!G9,"") -> 585000 | K22: =IF('ROSI & Prioritization'!H9<>"",'ROSI & Prioritization'!H9,"") -> 38 | L22: =IF(K22="","",IF(K22>20,"TIER 1 — IMMEDIATE",IF(K22>=10,"TIER 2 — HIGH PRIORITY",IF(K22>=3,"TIER 3 — STANDARD",IF(K22>=1,"TIER 4 — MONITOR","TIER 5 — DEPRIORITIZE"))))) -> TIER 1 — IMMEDIATE | M22: =IF(B22<>"",IFERROR(TODAY()-VLOOKUP(B22,'Issue Register'!A:D,4,0),""),"") -> 565 | N22: =IF(K22="","",IF(K22>20,"Immediate — no budget gate",IF(K22>=10,"Fix within 30 days",IF(K22>=3,"Schedule in 90-day roadmap",IF(K22>=1,"Accept or transfer risk","Formally accept — deprioritize"))))) -> Immediate — no budget gate
A23: =IF('ROSI & Prioritization'!B10<>"",6,"") -> 6 | B23: =IF('ROSI & Prioritization'!A10<>"",'ROSI & Prioritization'!A10,"") -> SEC-005 | C23: =IF('ROSI & Prioritization'!B10<>"",'ROSI & Prioritization'!B10,"") -> TLS 1.0 on API Gateway | D23: =IF(B23<>"",IFERROR(VLOOKUP(B23,'Issue Register'!A:H,8,0),""),"") -> Network | E23: =IF('ROSI & Prioritization'!C10<>"",'ROSI & Prioritization'!C10,"") -> High | F23: =IF(B23<>"",IFERROR(VLOOKUP(B23,'Issue Register'!A:G,7,0),""),"") -> Open | G23: =IF('ROSI & Prioritization'!D10<>"",'ROSI & Prioritization'!D10,"") -> 975000 | H23: =IF('ROSI & Prioritization'!E10<>"",'ROSI & Prioritization'!E10,"") -> 22000 | I23: =IF('ROSI & Prioritization'!F10<>"",'ROSI & Prioritization'!F10,"") -> 0.65 | J23: =IF('ROSI & Prioritization'!G10<>"",'ROSI & Prioritization'!G10,"") -> 633750 | K23: =IF('ROSI & Prioritization'!H10<>"",'ROSI & Prioritization'!H10,"") -> 27.806818 | L23: =IF(K23="","",IF(K23>20,"TIER 1 — IMMEDIATE",IF(K23>=10,"TIER 2 — HIGH PRIORITY",IF(K23>=3,"TIER 3 — STANDARD",IF(K23>=1,"TIER 4 — MONITOR","TIER 5 — DEPRIORITIZE"))))) -> TIER 1 — IMMEDIATE | M23: =IF(B23<>"",IFERROR(TODAY()-VLOOKUP(B23,'Issue Register'!A:D,4,0),""),"") -> 588 | N23: =IF(K23="","",IF(K23>20,"Immediate — no budget gate",IF(K23>=10,"Fix within 30 days",IF(K23>=3,"Schedule in 90-day roadmap",IF(K23>=1,"Accept or transfer risk","Formally accept — deprioritize"))))) -> Immediate — no budget gate
A24: =IF('ROSI & Prioritization'!B11<>"",7,"") -> 7 | B24: =IF('ROSI & Prioritization'!A11<>"",'ROSI & Prioritization'!A11,"") -> SEC-010 | C24: =IF('ROSI & Prioritization'!B11<>"",'ROSI & Prioritization'!B11,"") -> IDOR in HR Application | D24: =IF(B24<>"",IFERROR(VLOOKUP(B24,'Issue Register'!A:H,8,0),""),"") -> Application | E24: =IF('ROSI & Prioritization'!C11<>"",'ROSI & Prioritization'!C11,"") -> High | F24: =IF(B24<>"",IFERROR(VLOOKUP(B24,'Issue Register'!A:G,7,0),""),"") -> Open | G24: =IF('ROSI & Prioritization'!D11<>"",'ROSI & Prioritization'!D11,"") -> 975000 | H24: =IF('ROSI & Prioritization'!E11<>"",'ROSI & Prioritization'!E11,"") -> 28000 | I24: =IF('ROSI & Prioritization'!F11<>"",'ROSI & Prioritization'!F11,"") -> 0.75 | J24: =IF('ROSI & Prioritization'!G11<>"",'ROSI & Prioritization'!G11,"") -> 731250 | K24: =IF('ROSI & Prioritization'!H11<>"",'ROSI & Prioritization'!H11,"") -> 25.116071 | L24: =IF(K24="","",IF(K24>20,"TIER 1 — IMMEDIATE",IF(K24>=10,"TIER 2 — HIGH PRIORITY",IF(K24>=3,"TIER 3 — STANDARD",IF(K24>=1,"TIER 4 — MONITOR","TIER 5 — DEPRIORITIZE"))))) -> TIER 1 — IMMEDIATE | M24: =IF(B24<>"",IFERROR(TODAY()-VLOOKUP(B24,'Issue Register'!A:D,4,0),""),"") -> 575 | N24: =IF(K24="","",IF(K24>20,"Immediate — no budget gate",IF(K24>=10,"Fix within 30 days",IF(K24>=3,"Schedule in 90-day roadmap",IF(K24>=1,"Accept or transfer risk","Formally accept — deprioritize"))))) -> Immediate — no budget gate
A25: =IF('ROSI & Prioritization'!B12<>"",8,"") -> 8 | B25: =IF('ROSI & Prioritization'!A12<>"",'ROSI & Prioritization'!A12,"") -> SEC-015 | C25: =IF('ROSI & Prioritization'!B12<>"",'ROSI & Prioritization'!B12,"") -> Container CVEs in Production | D25: =IF(B25<>"",IFERROR(VLOOKUP(B25,'Issue Register'!A:H,8,0),""),"") -> Infrastructure | E25: =IF('ROSI & Prioritization'!C12<>"",'ROSI & Prioritization'!C12,"") -> High | F25: =IF(B25<>"",IFERROR(VLOOKUP(B25,'Issue Register'!A:G,7,0),""),"") -> Open | G25: =IF('ROSI & Prioritization'!D12<>"",'ROSI & Prioritization'!D12,"") -> 975000 | H25: =IF('ROSI & Prioritization'!E12<>"",'ROSI & Prioritization'!E12,"") -> 32000 | I25: =IF('ROSI & Prioritization'!F12<>"",'ROSI & Prioritization'!F12,"") -> 0.7 | J25: =IF('ROSI & Prioritization'!G12<>"",'ROSI & Prioritization'!G12,"") -> 682500 | K25: =IF('ROSI & Prioritization'!H12<>"",'ROSI & Prioritization'!H12,"") -> 20.328125 | L25: =IF(K25="","",IF(K25>20,"TIER 1 — IMMEDIATE",IF(K25>=10,"TIER 2 — HIGH PRIORITY",IF(K25>=3,"TIER 3 — STANDARD",IF(K25>=1,"TIER 4 — MONITOR","TIER 5 — DEPRIORITIZE"))))) -> TIER 1 — IMMEDIATE | M25: =IF(B25<>"",IFERROR(TODAY()-VLOOKUP(B25,'Issue Register'!A:D,4,0),""),"") -> 559 | N25: =IF(K25="","",IF(K25>20,"Immediate — no budget gate",IF(K25>=10,"Fix within 30 days",IF(K25>=3,"Schedule in 90-day roadmap",IF(K25>=1,"Accept or transfer risk","Formally accept — deprioritize"))))) -> Immediate — no budget gate
A26: =IF('ROSI & Prioritization'!B13<>"",9,"") -> 9 | B26: =IF('ROSI & Prioritization'!A13<>"",'ROSI & Prioritization'!A13,"") -> SEC-003 | C26: =IF('ROSI & Prioritization'!B13<>"",'ROSI & Prioritization'!B13,"") -> PII in Unencrypted S3 | D26: =IF(B26<>"",IFERROR(VLOOKUP(B26,'Issue Register'!A:H,8,0),""),"") -> Data Protection | E26: =IF('ROSI & Prioritization'!C13<>"",'ROSI & Prioritization'!C13,"") -> High | F26: =IF(B26<>"",IFERROR(VLOOKUP(B26,'Issue Register'!A:G,7,0),""),"") -> Open | G26: =IF('ROSI & Prioritization'!D13<>"",'ROSI & Prioritization'!D13,"") -> 975000 | H26: =IF('ROSI & Prioritization'!E13<>"",'ROSI & Prioritization'!E13,"") -> 45000 | I26: =IF('ROSI & Prioritization'!F13<>"",'ROSI & Prioritization'!F13,"") -> 0.8 | J26: =IF('ROSI & Prioritization'!G13<>"",'ROSI & Prioritization'!G13,"") -> 780000 | K26: =IF('ROSI & Prioritization'!H13<>"",'ROSI & Prioritization'!H13,"") -> 16.333333 | L26: =IF(K26="","",IF(K26>20,"TIER 1 — IMMEDIATE",IF(K26>=10,"TIER 2 — HIGH PRIORITY",IF(K26>=3,"TIER 3 — STANDARD",IF(K26>=1,"TIER 4 — MONITOR","TIER 5 — DEPRIORITIZE"))))) -> TIER 2 — HIGH PRIORITY | M26: =IF(B26<>"",IFERROR(TODAY()-VLOOKUP(B26,'Issue Register'!A:D,4,0),""),"") -> 592 | N26: =IF(K26="","",IF(K26>20,"Immediate — no budget gate",IF(K26>=10,"Fix within 30 days",IF(K26>=3,"Schedule in 90-day roadmap",IF(K26>=1,"Accept or transfer risk","Formally accept — deprioritize"))))) -> Fix within 30 days
A27: =IF('ROSI & Prioritization'!B14<>"",10,"") -> 10 | B27: =IF('ROSI & Prioritization'!A14<>"",'ROSI & Prioritization'!A14,"") -> SEC-011 | C27: =IF('ROSI & Prioritization'!B14<>"",'ROSI & Prioritization'!B14,"") -> SIEM Log Gaps | D27: =IF(B27<>"",IFERROR(VLOOKUP(B27,'Issue Register'!A:H,8,0),""),"") -> Detection & Response | E27: =IF('ROSI & Prioritization'!C14<>"",'ROSI & Prioritization'!C14,"") -> High | F27: =IF(B27<>"",IFERROR(VLOOKUP(B27,'Issue Register'!A:G,7,0),""),"") -> In Remediation | G27: =IF('ROSI & Prioritization'!D14<>"",'ROSI & Prioritization'!D14,"") -> 975000 | H27: =IF('ROSI & Prioritization'!E14<>"",'ROSI & Prioritization'!E14,"") -> 42000 | I27: =IF('ROSI & Prioritization'!F14<>"",'ROSI & Prioritization'!F14,"") -> 0.6 | J27: =IF('ROSI & Prioritization'!G14<>"",'ROSI & Prioritization'!G14,"") -> 585000 | K27: =IF('ROSI & Prioritization'!H14<>"",'ROSI & Prioritization'!H14,"") -> 12.928571 | L27: =IF(K27="","",IF(K27>20,"TIER 1 — IMMEDIATE",IF(K27>=10,"TIER 2 — HIGH PRIORITY",IF(K27>=3,"TIER 3 — STANDARD",IF(K27>=1,"TIER 4 — MONITOR","TIER 5 — DEPRIORITIZE"))))) -> TIER 2 — HIGH PRIORITY | M27: =IF(B27<>"",IFERROR(TODAY()-VLOOKUP(B27,'Issue Register'!A:D,4,0),""),"") -> 568 | N27: =IF(K27="","",IF(K27>20,"Immediate — no budget gate",IF(K27>=10,"Fix within 30 days",IF(K27>=3,"Schedule in 90-day roadmap",IF(K27>=1,"Accept or transfer risk","Formally accept — deprioritize"))))) -> Fix within 30 days
A28: =IF('ROSI & Prioritization'!B15<>"",11,"") -> 11 | B28: =IF('ROSI & Prioritization'!A15<>"",'ROSI & Prioritization'!A15,"") -> SEC-008 | C28: =IF('ROSI & Prioritization'!B15<>"",'ROSI & Prioritization'!B15,"") -> Endpoints without EDR | D28: =IF(B28<>"",IFERROR(VLOOKUP(B28,'Issue Register'!A:H,8,0),""),"") -> Endpoint | E28: =IF('ROSI & Prioritization'!C15<>"",'ROSI & Prioritization'!C15,"") -> Medium | F28: =IF(B28<>"",IFERROR(VLOOKUP(B28,'Issue Register'!A:G,7,0),""),"") -> Open | G28: =IF('ROSI & Prioritization'!D15<>"",'ROSI & Prioritization'!D15,"") -> 122500 | H28: =IF('ROSI & Prioritization'!E15<>"",'ROSI & Prioritization'!E15,"") -> 35000 | I28: =IF('ROSI & Prioritization'!F15<>"",'ROSI & Prioritization'!F15,"") -> 0.8 | J28: =IF('ROSI & Prioritization'!G15<>"",'ROSI & Prioritization'!G15,"") -> 98000 | K28: =IF('ROSI & Prioritization'!H15<>"",'ROSI & Prioritization'!H15,"") -> 1.8 | L28: =IF(K28="","",IF(K28>20,"TIER 1 — IMMEDIATE",IF(K28>=10,"TIER 2 — HIGH PRIORITY",IF(K28>=3,"TIER 3 — STANDARD",IF(K28>=1,"TIER 4 — MONITOR","TIER 5 — DEPRIORITIZE"))))) -> TIER 4 — MONITOR | M28: =IF(B28<>"",IFERROR(TODAY()-VLOOKUP(B28,'Issue Register'!A:D,4,0),""),"") -> 580 | N28: =IF(K28="","",IF(K28>20,"Immediate — no budget gate",IF(K28>=10,"Fix within 30 days",IF(K28>=3,"Schedule in 90-day roadmap",IF(K28>=1,"Accept or transfer risk","Formally accept — deprioritize"))))) -> Accept or transfer risk
A29: =IF('ROSI & Prioritization'!B16<>"",12,"") -> 12 | B29: =IF('ROSI & Prioritization'!A16<>"",'ROSI & Prioritization'!A16,"") -> SEC-014 | C29: =IF('ROSI & Prioritization'!B16<>"",'ROSI & Prioritization'!B16,"") -> DLP Not Configured | D29: =IF(B29<>"",IFERROR(VLOOKUP(B29,'Issue Register'!A:H,8,0),""),"") -> Data Protection | E29: =IF('ROSI & Prioritization'!C16<>"",'ROSI & Prioritization'!C16,"") -> Medium | F29: =IF(B29<>"",IFERROR(VLOOKUP(B29,'Issue Register'!A:G,7,0),""),"") -> Open | G29: =IF('ROSI & Prioritization'!D16<>"",'ROSI & Prioritization'!D16,"") -> 122500 | H29: =IF('ROSI & Prioritization'!E16<>"",'ROSI & Prioritization'!E16,"") -> 55000 | I29: =IF('ROSI & Prioritization'!F16<>"",'ROSI & Prioritization'!F16,"") -> 0.75 | J29: =IF('ROSI & Prioritization'!G16<>"",'ROSI & Prioritization'!G16,"") -> 91875 | K29: =IF('ROSI & Prioritization'!H16<>"",'ROSI & Prioritization'!H16,"") -> 0.67045455 | L29: =IF(K29="","",IF(K29>20,"TIER 1 — IMMEDIATE",IF(K29>=10,"TIER 2 — HIGH PRIORITY",IF(K29>=3,"TIER 3 — STANDARD",IF(K29>=1,"TIER 4 — MONITOR","TIER 5 — DEPRIORITIZE"))))) -> TIER 5 — DEPRIORITIZE | M29: =IF(B29<>"",IFERROR(TODAY()-VLOOKUP(B29,'Issue Register'!A:D,4,0),""),"") -> 561 | N29: =IF(K29="","",IF(K29>20,"Immediate — no budget gate",IF(K29>=10,"Fix within 30 days",IF(K29>=3,"Schedule in 90-day roadmap",IF(K29>=1,"Accept or transfer risk","Formally accept — deprioritize"))))) -> Formally accept — deprioritize
A30: =IF('ROSI & Prioritization'!B17<>"",13,"") -> 13 | B30: =IF('ROSI & Prioritization'!A17<>"",'ROSI & Prioritization'!A17,"") -> SEC-007 | C30: =IF('ROSI & Prioritization'!B17<>"",'ROSI & Prioritization'!B17,"") -> Missing Security Headers | D30: =IF(B30<>"",IFERROR(VLOOKUP(B30,'Issue Register'!A:H,8,0),""),"") -> Application | E30: =IF('ROSI & Prioritization'!C17<>"",'ROSI & Prioritization'!C17,"") -> Low | F30: =IF(B30<>"",IFERROR(VLOOKUP(B30,'Issue Register'!A:G,7,0),""),"") -> Open | G30: =IF('ROSI & Prioritization'!D17<>"",'ROSI & Prioritization'!D17,"") -> 7500 | H30: =IF('ROSI & Prioritization'!E17<>"",'ROSI & Prioritization'!E17,"") -> 5000 | I30: =IF('ROSI & Prioritization'!F17<>"",'ROSI & Prioritization'!F17,"") -> 0.95 | J30: =IF('ROSI & Prioritization'!G17<>"",'ROSI & Prioritization'!G17,"") -> 7125 | K30: =IF('ROSI & Prioritization'!H17<>"",'ROSI & Prioritization'!H17,"") -> 0.425 | L30: =IF(K30="","",IF(K30>20,"TIER 1 — IMMEDIATE",IF(K30>=10,"TIER 2 — HIGH PRIORITY",IF(K30>=3,"TIER 3 — STANDARD",IF(K30>=1,"TIER 4 — MONITOR","TIER 5 — DEPRIORITIZE"))))) -> TIER 5 — DEPRIORITIZE | M30: =IF(B30<>"",IFERROR(TODAY()-VLOOKUP(B30,'Issue Register'!A:D,4,0),""),"") -> 582 | N30: =IF(K30="","",IF(K30>20,"Immediate — no budget gate",IF(K30>=10,"Fix within 30 days",IF(K30>=3,"Schedule in 90-day roadmap",IF(K30>=1,"Accept or transfer risk","Formally accept — deprioritize"))))) -> Formally accept — deprioritize
A31: =IF('ROSI & Prioritization'!B18<>"",14,"") | B31: =IF('ROSI & Prioritization'!A18<>"",'ROSI & Prioritization'!A18,"") | C31: =IF('ROSI & Prioritization'!B18<>"",'ROSI & Prioritization'!B18,"") | D31: =IF(B31<>"",IFERROR(VLOOKUP(B31,'Issue Register'!A:H,8,0),""),"") | E31: =IF('ROSI & Prioritization'!C18<>"",'ROSI & Prioritization'!C18,"") | F31: =IF(B31<>"",IFERROR(VLOOKUP(B31,'Issue Register'!A:G,7,0),""),"") | G31: =IF('ROSI & Prioritization'!D18<>"",'ROSI & Prioritization'!D18,"") | H31: =IF('ROSI & Prioritization'!E18<>"",'ROSI & Prioritization'!E18,"") | I31: =IF('ROSI & Prioritization'!F18<>"",'ROSI & Prioritization'!F18,"") | J31: =IF('ROSI & Prioritization'!G18<>"",'ROSI & Prioritization'!G18,"") | K31: =IF('ROSI & Prioritization'!H18<>"",'ROSI & Prioritization'!H18,"") | L31: =IF(K31="","",IF(K31>20,"TIER 1 — IMMEDIATE",IF(K31>=10,"TIER 2 — HIGH PRIORITY",IF(K31>=3,"TIER 3 — STANDARD",IF(K31>=1,"TIER 4 — MONITOR","TIER 5 — DEPRIORITIZE"))))) | M31: =IF(B31<>"",IFERROR(TODAY()-VLOOKUP(B31,'Issue Register'!A:D,4,0),""),"") | N31: =IF(K31="","",IF(K31>20,"Immediate — no budget gate",IF(K31>=10,"Fix within 30 days",IF(K31>=3,"Schedule in 90-day roadmap",IF(K31>=1,"Accept or transfer risk","Formally accept — deprioritize")))))
A32: =IF('ROSI & Prioritization'!B19<>"",15,"") | B32: =IF('ROSI & Prioritization'!A19<>"",'ROSI & Prioritization'!A19,"") | C32: =IF('ROSI & Prioritization'!B19<>"",'ROSI & Prioritization'!B19,"") | D32: =IF(B32<>"",IFERROR(VLOOKUP(B32,'Issue Register'!A:H,8,0),""),"") | E32: =IF('ROSI & Prioritization'!C19<>"",'ROSI & Prioritization'!C19,"") | F32: =IF(B32<>"",IFERROR(VLOOKUP(B32,'Issue Register'!A:G,7,0),""),"") | G32: =IF('ROSI & Prioritization'!D19<>"",'ROSI & Prioritization'!D19,"") | H32: =IF('ROSI & Prioritization'!E19<>"",'ROSI & Prioritization'!E19,"") | I32: =IF('ROSI & Prioritization'!F19<>"",'ROSI & Prioritization'!F19,"") | J32: =IF('ROSI & Prioritization'!G19<>"",'ROSI & Prioritization'!G19,"") | K32: =IF('ROSI & Prioritization'!H19<>"",'ROSI & Prioritization'!H19,"") | L32: =IF(K32="","",IF(K32>20,"TIER 1 — IMMEDIATE",IF(K32>=10,"TIER 2 — HIGH PRIORITY",IF(K32>=3,"TIER 3 — STANDARD",IF(K32>=1,"TIER 4 — MONITOR","TIER 5 — DEPRIORITIZE"))))) | M32: =IF(B32<>"",IFERROR(TODAY()-VLOOKUP(B32,'Issue Register'!A:D,4,0),""),"") | N32: =IF(K32="","",IF(K32>20,"Immediate — no budget gate",IF(K32>=10,"Fix within 30 days",IF(K32>=3,"Schedule in 90-day roadmap",IF(K32>=1,"Accept or transfer risk","Formally accept — deprioritize")))))
A33: =IF('ROSI & Prioritization'!B20<>"",16,"") | B33: =IF('ROSI & Prioritization'!A20<>"",'ROSI & Prioritization'!A20,"") -> ROSI INTERPRETATION GUIDE & INVESTMENT RECOMMENDATION | C33: =IF('ROSI & Prioritization'!B20<>"",'ROSI & Prioritization'!B20,"") | D33: =IF(B33<>"",IFERROR(VLOOKUP(B33,'Issue Register'!A:H,8,0),""),"") | E33: =IF('ROSI & Prioritization'!C20<>"",'ROSI & Prioritization'!C20,"") | F33: =IF(B33<>"",IFERROR(VLOOKUP(B33,'Issue Register'!A:G,7,0),""),"") | G33: =IF('ROSI & Prioritization'!D20<>"",'ROSI & Prioritization'!D20,"") | H33: =IF('ROSI & Prioritization'!E20<>"",'ROSI & Prioritization'!E20,"") | I33: =IF('ROSI & Prioritization'!F20<>"",'ROSI & Prioritization'!F20,"") | J33: =IF('ROSI & Prioritization'!G20<>"",'ROSI & Prioritization'!G20,"") | K33: =IF('ROSI & Prioritization'!H20<>"",'ROSI & Prioritization'!H20,"") | L33: =IF(K33="","",IF(K33>20,"TIER 1 — IMMEDIATE",IF(K33>=10,"TIER 2 — HIGH PRIORITY",IF(K33>=3,"TIER 3 — STANDARD",IF(K33>=1,"TIER 4 — MONITOR","TIER 5 — DEPRIORITIZE"))))) | M33: =IF(B33<>"",IFERROR(TODAY()-VLOOKUP(B33,'Issue Register'!A:D,4,0),""),"") | N33: =IF(K33="","",IF(K33>20,"Immediate — no budget gate",IF(K33>=10,"Fix within 30 days",IF(K33>=3,"Schedule in 90-day roadmap",IF(K33>=1,"Accept or transfer risk","Formally accept — deprioritize")))))
A34: =IF('ROSI & Prioritization'!B21<>"",17,"") -> 17 | B34: =IF('ROSI & Prioritization'!A21<>"",'ROSI & Prioritization'!A21,"") -> ROSI Band | C34: =IF('ROSI & Prioritization'!B21<>"",'ROSI & Prioritization'!B21,"") -> Recommended Action | D34: =IF(B34<>"",IFERROR(VLOOKUP(B34,'Issue Register'!A:H,8,0),""),"") | E34: =IF('ROSI & Prioritization'!C21<>"",'ROSI & Prioritization'!C21,"") | F34: =IF(B34<>"",IFERROR(VLOOKUP(B34,'Issue Register'!A:G,7,0),""),"") | G34: =IF('ROSI & Prioritization'!D21<>"",'ROSI & Prioritization'!D21,"") | H34: =IF('ROSI & Prioritization'!E21<>"",'ROSI & Prioritization'!E21,"") | I34: =IF('ROSI & Prioritization'!F21<>"",'ROSI & Prioritization'!F21,"") | J34: =IF('ROSI & Prioritization'!G21<>"",'ROSI & Prioritization'!G21,"") | K34: =IF('ROSI & Prioritization'!H21<>"",'ROSI & Prioritization'!H21,"") | L34: =IF(K34="","",IF(K34>20,"TIER 1 — IMMEDIATE",IF(K34>=10,"TIER 2 — HIGH PRIORITY",IF(K34>=3,"TIER 3 — STANDARD",IF(K34>=1,"TIER 4 — MONITOR","TIER 5 — DEPRIORITIZE"))))) | M34: =IF(B34<>"",IFERROR(TODAY()-VLOOKUP(B34,'Issue Register'!A:D,4,0),""),"") | N34: =IF(K34="","",IF(K34>20,"Immediate — no budget gate",IF(K34>=10,"Fix within 30 days",IF(K34>=3,"Schedule in 90-day roadmap",IF(K34>=1,"Accept or transfer risk","Formally accept — deprioritize")))))
A35: =IF('ROSI & Prioritization'!B22<>"",18,"") -> 18 | B35: =IF('ROSI & Prioritization'!A22<>"",'ROSI & Prioritization'!A22,"") -> ROSI > 10x | C35: =IF('ROSI & Prioritization'!B22<>"",'ROSI & Prioritization'!B22,"") -> Exceptional — Immediate prioritization; funding should not be a barrier | D35: =IF(B35<>"",IFERROR(VLOOKUP(B35,'Issue Register'!A:H,8,0),""),"") | E35: =IF('ROSI & Prioritization'!C22<>"",'ROSI & Prioritization'!C22,"") | F35: =IF(B35<>"",IFERROR(VLOOKUP(B35,'Issue Register'!A:G,7,0),""),"") | G35: =IF('ROSI & Prioritization'!D22<>"",'ROSI & Prioritization'!D22,"") | H35: =IF('ROSI & Prioritization'!E22<>"",'ROSI & Prioritization'!E22,"") | I35: =IF('ROSI & Prioritization'!F22<>"",'ROSI & Prioritization'!F22,"") | J35: =IF('ROSI & Prioritization'!G22<>"",'ROSI & Prioritization'!G22,"") | K35: =IF('ROSI & Prioritization'!H22<>"",'ROSI & Prioritization'!H22,"") | L35: =IF(K35="","",IF(K35>20,"TIER 1 — IMMEDIATE",IF(K35>=10,"TIER 2 — HIGH PRIORITY",IF(K35>=3,"TIER 3 — STANDARD",IF(K35>=1,"TIER 4 — MONITOR","TIER 5 — DEPRIORITIZE"))))) | M35: =IF(B35<>"",IFERROR(TODAY()-VLOOKUP(B35,'Issue Register'!A:D,4,0),""),"") | N35: =IF(K35="","",IF(K35>20,"Immediate — no budget gate",IF(K35>=10,"Fix within 30 days",IF(K35>=3,"Schedule in 90-day roadmap",IF(K35>=1,"Accept or transfer risk","Formally accept — deprioritize")))))
A36: =IF('ROSI & Prioritization'!B23<>"",19,"") -> 19 | B36: =IF('ROSI & Prioritization'!A23<>"",'ROSI & Prioritization'!A23,"") -> ROSI 5x–10x | C36: =IF('ROSI & Prioritization'!B23<>"",'ROSI & Prioritization'!B23,"") -> Strong — High priority; include in next sprint/quarter budget | D36: =IF(B36<>"",IFERROR(VLOOKUP(B36,'Issue Register'!A:H,8,0),""),"") | E36: =IF('ROSI & Prioritization'!C23<>"",'ROSI & Prioritization'!C23,"") | F36: =IF(B36<>"",IFERROR(VLOOKUP(B36,'Issue Register'!A:G,7,0),""),"") | G36: =IF('ROSI & Prioritization'!D23<>"",'ROSI & Prioritization'!D23,"") | H36: =IF('ROSI & Prioritization'!E23<>"",'ROSI & Prioritization'!E23,"") | I36: =IF('ROSI & Prioritization'!F23<>"",'ROSI & Prioritization'!F23,"") | J36: =IF('ROSI & Prioritization'!G23<>"",'ROSI & Prioritization'!G23,"") | K36: =IF('ROSI & Prioritization'!H23<>"",'ROSI & Prioritization'!H23,"") | L36: =IF(K36="","",IF(K36>20,"TIER 1 — IMMEDIATE",IF(K36>=10,"TIER 2 — HIGH PRIORITY",IF(K36>=3,"TIER 3 — STANDARD",IF(K36>=1,"TIER 4 — MONITOR","TIER 5 — DEPRIORITIZE"))))) | M36: =IF(B36<>"",IFERROR(TODAY()-VLOOKUP(B36,'Issue Register'!A:D,4,0),""),"") | N36: =IF(K36="","",IF(K36>20,"Immediate — no budget gate",IF(K36>=10,"Fix within 30 days",IF(K36>=3,"Schedule in 90-day roadmap",IF(K36>=1,"Accept or transfer risk","Formally accept — deprioritize")))))
A37: =IF('ROSI & Prioritization'!B24<>"",20,"") -> 20 | B37: =IF('ROSI & Prioritization'!A24<>"",'ROSI & Prioritization'!A24,"") -> ROSI 2x–5x | C37: =IF('ROSI & Prioritization'!B24<>"",'ROSI & Prioritization'!B24,"") -> Good — Standard prioritization; schedule within risk appetite window | D37: =IF(B37<>"",IFERROR(VLOOKUP(B37,'Issue Register'!A:H,8,0),""),"") | E37: =IF('ROSI & Prioritization'!C24<>"",'ROSI & Prioritization'!C24,"") | F37: =IF(B37<>"",IFERROR(VLOOKUP(B37,'Issue Register'!A:G,7,0),""),"") | G37: =IF('ROSI & Prioritization'!D24<>"",'ROSI & Prioritization'!D24,"") | H37: =IF('ROSI & Prioritization'!E24<>"",'ROSI & Prioritization'!E24,"") | I37: =IF('ROSI & Prioritization'!F24<>"",'ROSI & Prioritization'!F24,"") | J37: =IF('ROSI & Prioritization'!G24<>"",'ROSI & Prioritization'!G24,"") | K37: =IF('ROSI & Prioritization'!H24<>"",'ROSI & Prioritization'!H24,"") | L37: =IF(K37="","",IF(K37>20,"TIER 1 — IMMEDIATE",IF(K37>=10,"TIER 2 — HIGH PRIORITY",IF(K37>=3,"TIER 3 — STANDARD",IF(K37>=1,"TIER 4 — MONITOR","TIER 5 — DEPRIORITIZE"))))) | M37: =IF(B37<>"",IFERROR(TODAY()-VLOOKUP(B37,'Issue Register'!A:D,4,0),""),"") | N37: =IF(K37="","",IF(K37>20,"Immediate — no budget gate",IF(K37>=10,"Fix within 30 days",IF(K37>=3,"Schedule in 90-day roadmap",IF(K37>=1,"Accept or transfer risk","Formally accept — deprioritize")))))
A38: =IF('ROSI & Prioritization'!B25<>"",21,"") -> 21 | B38: =IF('ROSI & Prioritization'!A25<>"",'ROSI & Prioritization'!A25,"") -> ROSI 1x–2x | C38: =IF('ROSI & Prioritization'!B25<>"",'ROSI & Prioritization'!B25,"") -> Marginal — Evaluate vs. risk transfer (insurance) or risk acceptance | D38: =IF(B38<>"",IFERROR(VLOOKUP(B38,'Issue Register'!A:H,8,0),""),"") | E38: =IF('ROSI & Prioritization'!C25<>"",'ROSI & Prioritization'!C25,"") | F38: =IF(B38<>"",IFERROR(VLOOKUP(B38,'Issue Register'!A:G,7,0),""),"") | G38: =IF('ROSI & Prioritization'!D25<>"",'ROSI & Prioritization'!D25,"") | H38: =IF('ROSI & Prioritization'!E25<>"",'ROSI & Prioritization'!E25,"") | I38: =IF('ROSI & Prioritization'!F25<>"",'ROSI & Prioritization'!F25,"") | J38: =IF('ROSI & Prioritization'!G25<>"",'ROSI & Prioritization'!G25,"") | K38: =IF('ROSI & Prioritization'!H25<>"",'ROSI & Prioritization'!H25,"") | L38: =IF(K38="","",IF(K38>20,"TIER 1 — IMMEDIATE",IF(K38>=10,"TIER 2 — HIGH PRIORITY",IF(K38>=3,"TIER 3 — STANDARD",IF(K38>=1,"TIER 4 — MONITOR","TIER 5 — DEPRIORITIZE"))))) | M38: =IF(B38<>"",IFERROR(TODAY()-VLOOKUP(B38,'Issue Register'!A:D,4,0),""),"") | N38: =IF(K38="","",IF(K38>20,"Immediate — no budget gate",IF(K38>=10,"Fix within 30 days",IF(K38>=3,"Schedule in 90-day roadmap",IF(K38>=1,"Accept or transfer risk","Formally accept — deprioritize")))))
A39: =IF('ROSI & Prioritization'!B26<>"",22,"") -> 22 | B39: =IF('ROSI & Prioritization'!A26<>"",'ROSI & Prioritization'!A26,"") -> ROSI < 1x | C39: =IF('ROSI & Prioritization'!B26<>"",'ROSI & Prioritization'!B26,"") -> Poor — Consider risk transfer, compensating controls, or formal acceptance | D39: =IF(B39<>"",IFERROR(VLOOKUP(B39,'Issue Register'!A:H,8,0),""),"") | E39: =IF('ROSI & Prioritization'!C26<>"",'ROSI & Prioritization'!C26,"") | F39: =IF(B39<>"",IFERROR(VLOOKUP(B39,'Issue Register'!A:G,7,0),""),"") | G39: =IF('ROSI & Prioritization'!D26<>"",'ROSI & Prioritization'!D26,"") | H39: =IF('ROSI & Prioritization'!E26<>"",'ROSI & Prioritization'!E26,"") | I39: =IF('ROSI & Prioritization'!F26<>"",'ROSI & Prioritization'!F26,"") | J39: =IF('ROSI & Prioritization'!G26<>"",'ROSI & Prioritization'!G26,"") | K39: =IF('ROSI & Prioritization'!H26<>"",'ROSI & Prioritization'!H26,"") | L39: =IF(K39="","",IF(K39>20,"TIER 1 — IMMEDIATE",IF(K39>=10,"TIER 2 — HIGH PRIORITY",IF(K39>=3,"TIER 3 — STANDARD",IF(K39>=1,"TIER 4 — MONITOR","TIER 5 — DEPRIORITIZE"))))) | M39: =IF(B39<>"",IFERROR(TODAY()-VLOOKUP(B39,'Issue Register'!A:D,4,0),""),"") | N39: =IF(K39="","",IF(K39>20,"Immediate — no budget gate",IF(K39>=10,"Fix within 30 days",IF(K39>=3,"Schedule in 90-day roadmap",IF(K39>=1,"Accept or transfer risk","Formally accept — deprioritize")))))
A40: =IF('ROSI & Prioritization'!B27<>"",23,"") -> 23 | B40: =IF('ROSI & Prioritization'!A27<>"",'ROSI & Prioritization'!A27,"") -> Negative ROSI | C40: =IF('ROSI & Prioritization'!B27<>"",'ROSI & Prioritization'!B27,"") -> Remediation cost exceeds expected ALE — formally accept or transfer risk | D40: =IF(B40<>"",IFERROR(VLOOKUP(B40,'Issue Register'!A:H,8,0),""),"") | E40: =IF('ROSI & Prioritization'!C27<>"",'ROSI & Prioritization'!C27,"") | F40: =IF(B40<>"",IFERROR(VLOOKUP(B40,'Issue Register'!A:G,7,0),""),"") | G40: =IF('ROSI & Prioritization'!D27<>"",'ROSI & Prioritization'!D27,"") | H40: =IF('ROSI & Prioritization'!E27<>"",'ROSI & Prioritization'!E27,"") | I40: =IF('ROSI & Prioritization'!F27<>"",'ROSI & Prioritization'!F27,"") | J40: =IF('ROSI & Prioritization'!G27<>"",'ROSI & Prioritization'!G27,"") | K40: =IF('ROSI & Prioritization'!H27<>"",'ROSI & Prioritization'!H27,"") | L40: =IF(K40="","",IF(K40>20,"TIER 1 — IMMEDIATE",IF(K40>=10,"TIER 2 — HIGH PRIORITY",IF(K40>=3,"TIER 3 — STANDARD",IF(K40>=1,"TIER 4 — MONITOR","TIER 5 — DEPRIORITIZE"))))) | M40: =IF(B40<>"",IFERROR(TODAY()-VLOOKUP(B40,'Issue Register'!A:D,4,0),""),"") | N40: =IF(K40="","",IF(K40>20,"Immediate — no budget gate",IF(K40>=10,"Fix within 30 days",IF(K40>=3,"Schedule in 90-day roadmap",IF(K40>=1,"Accept or transfer risk","Formally accept — deprioritize")))))
A41: =IF('ROSI & Prioritization'!B28<>"",24,"") | B41: =IF('ROSI & Prioritization'!A28<>"",'ROSI & Prioritization'!A28,"") | C41: =IF('ROSI & Prioritization'!B28<>"",'ROSI & Prioritization'!B28,"") | D41: =IF(B41<>"",IFERROR(VLOOKUP(B41,'Issue Register'!A:H,8,0),""),"") | E41: =IF('ROSI & Prioritization'!C28<>"",'ROSI & Prioritization'!C28,"") | F41: =IF(B41<>"",IFERROR(VLOOKUP(B41,'Issue Register'!A:G,7,0),""),"") | G41: =IF('ROSI & Prioritization'!D28<>"",'ROSI & Prioritization'!D28,"") | H41: =IF('ROSI & Prioritization'!E28<>"",'ROSI & Prioritization'!E28,"") | I41: =IF('ROSI & Prioritization'!F28<>"",'ROSI & Prioritization'!F28,"") | J41: =IF('ROSI & Prioritization'!G28<>"",'ROSI & Prioritization'!G28,"") | K41: =IF('ROSI & Prioritization'!H28<>"",'ROSI & Prioritization'!H28,"") | L41: =IF(K41="","",IF(K41>20,"TIER 1 — IMMEDIATE",IF(K41>=10,"TIER 2 — HIGH PRIORITY",IF(K41>=3,"TIER 3 — STANDARD",IF(K41>=1,"TIER 4 — MONITOR","TIER 5 — DEPRIORITIZE"))))) | M41: =IF(B41<>"",IFERROR(TODAY()-VLOOKUP(B41,'Issue Register'!A:D,4,0),""),"") | N41: =IF(K41="","",IF(K41>20,"Immediate — no budget gate",IF(K41>=10,"Fix within 30 days",IF(K41>=3,"Schedule in 90-day roadmap",IF(K41>=1,"Accept or transfer risk","Formally accept — deprioritize")))))
A42: =IF('ROSI & Prioritization'!B29<>"",25,"") | B42: =IF('ROSI & Prioritization'!A29<>"",'ROSI & Prioritization'!A29,"") | C42: =IF('ROSI & Prioritization'!B29<>"",'ROSI & Prioritization'!B29,"") | D42: =IF(B42<>"",IFERROR(VLOOKUP(B42,'Issue Register'!A:H,8,0),""),"") | E42: =IF('ROSI & Prioritization'!C29<>"",'ROSI & Prioritization'!C29,"") | F42: =IF(B42<>"",IFERROR(VLOOKUP(B42,'Issue Register'!A:G,7,0),""),"") | G42: =IF('ROSI & Prioritization'!D29<>"",'ROSI & Prioritization'!D29,"") | H42: =IF('ROSI & Prioritization'!E29<>"",'ROSI & Prioritization'!E29,"") | I42: =IF('ROSI & Prioritization'!F29<>"",'ROSI & Prioritization'!F29,"") | J42: =IF('ROSI & Prioritization'!G29<>"",'ROSI & Prioritization'!G29,"") | K42: =IF('ROSI & Prioritization'!H29<>"",'ROSI & Prioritization'!H29,"") | L42: =IF(K42="","",IF(K42>20,"TIER 1 — IMMEDIATE",IF(K42>=10,"TIER 2 — HIGH PRIORITY",IF(K42>=3,"TIER 3 — STANDARD",IF(K42>=1,"TIER 4 — MONITOR","TIER 5 — DEPRIORITIZE"))))) | M42: =IF(B42<>"",IFERROR(TODAY()-VLOOKUP(B42,'Issue Register'!A:D,4,0),""),"") | N42: =IF(K42="","",IF(K42>20,"Immediate — no budget gate",IF(K42>=10,"Fix within 30 days",IF(K42>=3,"Schedule in 90-day roadmap",IF(K42>=1,"Accept or transfer risk","Formally accept — deprioritize")))))
A43: TOTALS (open issues only) | G43: =SUMIF(F18:F42,"<>Closed",G18:G42) -> 15102500 | H43: =SUMIF(F18:F42,"<>Closed",H18:H42) -> 369000 | J43: =SUMIF(F18:F42,"<>Closed",J18:J42) -> 12069500
...

Sheet Risk Domain Heat Map
A1: RISK DOMAIN HEAT MAP — ISSUE DISTRIBUTION & FINANCIAL EXPOSURE
A3: ℹ Domain counts and ALE totals update automatically as issues are added to the Issue Register. RAG status is a manual judgment — update when domain posture changes.
A4: Risk Domain | B4: Total Issues | C4: Critical | D4: High | E4: Medium | F4: Low | G4: Total ALE ($) | H4: Avg Risk Score | I4: Domain RAG
A5: Application Security | B5: =COUNTIF('Issue Register'!H:H,"Application Security") -> 0 | C5: =COUNTIFS('Issue Register'!H:H,"Application Security",'Issue Register'!I:I,"Critical") -> 0 | D5: =COUNTIFS('Issue Register'!H:H,"Application Security",'Issue Register'!I:I,"High") -> 0 | E5: =COUNTIFS('Issue Register'!H:H,"Application Security",'Issue Register'!I:I,"Medium") -> 0 | F5: =COUNTIFS('Issue Register'!H:H,"Application Security",'Issue Register'!I:I,"Low") -> 0 | G5: =SUMIF('Issue Register'!H:H,"Application Security",'Issue Register'!Q:Q) -> 0 | H5: =IFERROR(AVERAGEIF('Issue Register'!H:H,"Application Security",'Issue Register'!M:M),0) -> 0 | I5: Red
A6: Infrastructure | B6: =COUNTIF('Issue Register'!H:H,"Infrastructure") -> 3 | C6: =COUNTIFS('Issue Register'!H:H,"Infrastructure",'Issue Register'!I:I,"Critical") -> 2 | D6: =COUNTIFS('Issue Register'!H:H,"Infrastructure",'Issue Register'!I:I,"High") -> 1 | E6: =COUNTIFS('Issue Register'!H:H,"Infrastructure",'Issue Register'!I:I,"Medium") -> 0 | F6: =COUNTIFS('Issue Register'!H:H,"Infrastructure",'Issue Register'!I:I,"Low") -> 0 | G6: =SUMIF('Issue Register'!H:H,"Infrastructure",'Issue Register'!Q:Q) -> 5700000 | H6: =IFERROR(AVERAGEIF('Issue Register'!H:H,"Infrastructure",'Issue Register'!M:M),0) -> 6.2358333 | I6: Red
A7: Identity & Access | B7: =COUNTIF('Issue Register'!H:H,"Identity & Access") -> 2 | C7: =COUNTIFS('Issue Register'!H:H,"Identity & Access",'Issue Register'!I:I,"Critical") -> 0 | D7: =COUNTIFS('Issue Register'!H:H,"Identity & Access",'Issue Register'!I:I,"High") -> 1 | E7: =COUNTIFS('Issue Register'!H:H,"Identity & Access",'Issue Register'!I:I,"Medium") -> 1 | F7: =COUNTIFS('Issue Register'!H:H,"Identity & Access",'Issue Register'!I:I,"Low") -> 0 | G7: =SUMIF('Issue Register'!H:H,"Identity & Access",'Issue Register'!Q:Q) -> 1097500 | H7: =IFERROR(AVERAGEIF('Issue Register'!H:H,"Identity & Access",'Issue Register'!M:M),0) -> 2.16125 | I7: Amber
A8: Data Protection | B8: =COUNTIF('Issue Register'!H:H,"Data Protection") -> 2 | C8: =COUNTIFS('Issue Register'!H:H,"Data Protection",'Issue Register'!I:I,"Critical") -> 0 | D8: =COUNTIFS('Issue Register'!H:H,"Data Protection",'Issue Register'!I:I,"High") -> 1 | E8: =COUNTIFS('Issue Register'!H:H,"Data Protection",'Issue Register'!I:I,"Medium") -> 1 | F8: =COUNTIFS('Issue Register'!H:H,"Data Protection",'Issue Register'!I:I,"Low") -> 0 | G8: =SUMIF('Issue Register'!H:H,"Data Protection",'Issue Register'!Q:Q) -> 1097500 | H8: =IFERROR(AVERAGEIF('Issue Register'!H:H,"Data Protection",'Issue Register'!M:M),0) -> 1.9075 | I8: Amber
A9: Network Security | B9: =COUNTIF('Issue Register'!H:H,"Network Security") -> 0 | C9: =COUNTIFS('Issue Register'!H:H,"Network Security",'Issue Register'!I:I,"Critical") -> 0 | D9: =COUNTIFS('Issue Register'!H:H,"Network Security",'Issue Register'!I:I,"High") -> 0 | E9: =COUNTIFS('Issue Register'!H:H,"Network Security",'Issue Register'!I:I,"Medium") -> 0 | F9: =COUNTIFS('Issue Register'!H:H,"Network Security",'Issue Register'!I:I,"Low") -> 0 | G9: =SUMIF('Issue Register'!H:H,"Network Security",'Issue Register'!Q:Q) -> 0 | H9: =IFERROR(AVERAGEIF('Issue Register'!H:H,"Network Security",'Issue Register'!M:M),0) -> 0 | I9: Amber
A10: Endpoint Security | B10: =COUNTIF('Issue Register'!H:H,"Endpoint Security") -> 0 | C10: =COUNTIFS('Issue Register'!H:H,"Endpoint Security",'Issue Register'!I:I,"Critical") -> 0 | D10: =COUNTIFS('Issue Register'!H:H,"Endpoint Security",'Issue Register'!I:I,"High") -> 0 | E10: =COUNTIFS('Issue Register'!H:H,"Endpoint Security",'Issue Register'!I:I,"Medium") -> 0 | F10: =COUNTIFS('Issue Register'!H:H,"Endpoint Security",'Issue Register'!I:I,"Low") -> 0 | G10: =SUMIF('Issue Register'!H:H,"Endpoint Security",'Issue Register'!Q:Q) -> 0 | H10: =IFERROR(AVERAGEIF('Issue Register'!H:H,"Endpoint Security",'Issue Register'!M:M),0) -> 0 | I10: Green
A11: Detection & Response | B11: =COUNTIF('Issue Register'!H:H,"Detection & Response") -> 1 | C11: =COUNTIFS('Issue Register'!H:H,"Detection & Response",'Issue Register'!I:I,"Critical") -> 0 | D11: =COUNTIFS('Issue Register'!H:H,"Detection & Response",'Issue Register'!I:I,"High") -> 0 | E11: =COUNTIFS('Issue Register'!H:H,"Detection & Response",'Issue Register'!I:I,"Medium") -> 0 | F11: =COUNTIFS('Issue Register'!H:H,"Detection & Response",'Issue Register'!I:I,"Low") -> 0 | G11: =SUMIF('Issue Register'!H:H,"Detection & Response",'Issue Register'!Q:Q) -> 975000 | H11: =IFERROR(AVERAGEIF('Issue Register'!H:H,"Detection & Response",'Issue Register'!M:M),0) -> 2.275 | I11: Green
A12: Third-Party Risk | B12: =COUNTIF('Issue Register'!H:H,"Third-Party Risk") -> 1 | C12: =COUNTIFS('Issue Register'!H:H,"Third-Party Risk",'Issue Register'!I:I,"Critical") -> 0 | D12: =COUNTIFS('Issue Register'!H:H,"Third-Party Risk",'Issue Register'!I:I,"High") -> 1 | E12: =COUNTIFS('Issue Register'!H:H,"Third-Party Risk",'Issue Register'!I:I,"Medium") -> 0 | F12: =COUNTIFS('Issue Register'!H:H,"Third-Party Risk",'Issue Register'!I:I,"Low") -> 0 | G12: =SUMIF('Issue Register'!H:H,"Third-Party Risk",'Issue Register'!Q:Q) -> 975000 | H12: =IFERROR(AVERAGEIF('Issue Register'!H:H,"Third-Party Risk",'Issue Register'!M:M),0) -> 2.73 | I12: Green
A13: PORTFOLIO TOTALS | B13: =SUM(B5:B12) -> 9 | C13: =SUM(C5:C12) -> 2 | D13: =SUM(D5:D12) -> 4 | E13: =SUM(E5:E12) -> 2 | F13: =SUM(F5:F12) -> 0 | G13: =SUM(G5:G12) -> 9845000 | H13: =IFERROR(AVERAGE(H5:H12),0) -> 1.9136979 | I13: —
A15: 5×5 LIKELIHOOD × IMPACT HEAT MAP
